import unittest
from traceback import print_exception
import sys

def read_file(filename):
    file = open(filename, 'r')
    ret = file.readlines()
    for i, l in enumerate(ret):
        ret[i] = l.strip()
    file.close()
    return ret

def main(inputs):
    answers = []
    try:
        for input in inputs:
            # your code here
            answer = sum([int(n)*pow(-1,i) for i, n in enumerate(input[0].split())])
            answers.append(answer)
        return answers
    except Exception:
        print(f"===========================================================================")
        print(f"Failed in the case below")
        print(f"input: {input}")
        exc_info = sys.exc_info()
        print_exception(*exc_info)
        print(f"===========================================================================")
        del exc_info
class TestCases(unittest.TestCase):
    def test_input_txt(self):
        inputs, answers = [], []
        for i in range(1, 1 + 1):
            inputs.append(read_file(f"A-B/input{i}.txt"))
            answers.append(int(read_file(f"A-B/output{i}.txt")[0]))
        self.assertEqual(main(inputs), answers)


if __name__ == '__main__':
    unittest.main()